<?xml version="1.0"?>
<robot name="robot1">

    <link name="world_link"/>

    <link name="base_link">
        <inertial>
            <origin xyz="0.0 0.0 0.05" rpy="0.0 0.0 0.0"/>
            <mass value="0.5"/>
            <inertia ixx="0.004167" ixy="0.0" ixz="0.0" iyy="0.002083" iyz="0.0" izz="0.00541"/>
        </inertial>
        <visual >
            <origin xyz="0.0 0.0 0.05" rpy="0.0 0.0 0.0"/>
            <geometry>
                <box size="0.2 0.3 0.1"/>
            </geometry>
            <material name="white">
                <color rgba="1.0 1.0 1.0 1.0"/>
            </material>
        </visual>
        <collision>
            <origin xyz="0.0 0.0 0.05" rpy="0.0 0.0 0.0"/>
            <geometry>
                <box size="0.2 0.3 0.1"/>
            </geometry>
        </collision>
    </link>
    <joint name="joint_0" type="continuous">
        <parent link="world_link"/>
        <child link="base_link"/>
        <axis xyz="0 0 1"/>
        <origin xyz="0.0 0.0 0.05" rpy="0.0 0.0 1.0"/>
    </joint>
    
    <link name="wheel_1">
        <inertial>
            <origin xyz="0.12 0.1 0.0" rpy="0.0 1.5 0.0"/>
            <mass value="0.1"/>
            <inertia ixx="0.0" ixy="0.0" ixz="0.0" iyy="0.0" iyz="0.0" izz="0.0"/>
        </inertial>
        <visual>
            <origin xyz="0.0 0 0.0" rpy="0.0 0.0 0.0"/>
            <geometry>
                <cylinder radius="0.05" length="0.05"/>
            </geometry>
            <material name="black">
                <color rgba="0.0 0.0 0.0 1.0"/>
            </material>
        </visual>
        <collision>
            <origin xyz="0.12 0.1 0.0" rpy="0.0 1.5 0.0"/>
            <geometry>
                <cylinder radius="0.05" length="0.05"/>
            </geometry>
        </collision>
    </link>

    <joint name="joint_1" type="continuous">
        <parent link="base_link"/>
        <child link="wheel_1"/>
        <axis xyz="0 0 1"/>
        <origin xyz="0.12 0.1 0.0" rpy="0.0 1.5 0.0"/>
    </joint>
    


    <link name="wheel_2">
        <inertial>
            <origin xyz="-0.12 0.1 0.0" rpy="0.0 1.5 0.0"/>
            <mass value="0.2"/>
            <inertia ixx="0.0" ixy="0.0" ixz="0.0" iyy="0.0" iyz="0.0" izz="0.0"/>
        </inertial>
        <visual >
            <origin xyz="0 0 0.0" rpy="0.0 0 0.0"/>
            <geometry>
                <cylinder radius="0.05" length="0.05"/>
            </geometry>
            <material name="black">
                <color rgba="0.0 0.0 0.0 1.0"/>
            </material>
        </visual>
        <collision>
            <origin xyz="-0.12 0.1 0.0" rpy="0.0 1.5 0.0"/>
            <geometry>
                <cylinder radius="0.05" length="0.05"/>
            </geometry>
        </collision>
    </link>

    <joint name="joint_2" type="continuous">
        <parent link="base_link"/>
        <child link="wheel_2"/>
        <axis xyz="0 0 1"/>
        <origin xyz="-0.12 0.1 0.0" rpy="0.0 1.5 0.0"/>
    </joint>

    <link name="wheel_3">
        <inertial>
            <origin xyz="0.12 -0.1 0.0" rpy="0.0 1.5 0.0"/>
            <mass value="0.2"/>
            <inertia ixx="0.0" ixy="0.0" ixz="0.0" iyy="0.0" iyz="0.0" izz="0.0"/>
        </inertial>
        <visual >
            <origin xyz="0 0 0" rpy="0 0 0"/>
            <geometry>
                <cylinder radius="0.05" length="0.05"/>
            </geometry>
            <material name="black">
                <color rgba="0.0 0.0 0.0 1.0"/>
            </material>
        </visual>
        <collision>
            <origin xyz="0.12 -0.1 0.0" rpy="0.0 1.5 0.0"/>
            <geometry>
                <cylinder radius="0.05" length="0.05"/>
            </geometry>
        </collision>
    </link>

    <joint name="joint_3" type="continuous">
        <parent link="base_link"/>
        <child link="wheel_3"/>
        <axis xyz="0 0 1"/>
        <origin xyz="0.12 -0.1 0.0" rpy="0.0 1.5 0.0"/>
    </joint>
    
    <link name="wheel_4">
        <inertial>
            <origin xyz="-0.12 -0.1 0.0" rpy="0.0 1.5 0.0"/>
            <mass value="0.2"/>
            <inertia ixx="0.0" ixy="0.0" ixz="0.0" iyy="0.0" iyz="0.0" izz="0.0"/>
        </inertial>
        <visual >
            <origin xyz="0 0 0" rpy="0 0 0"/>
            <geometry>
                <cylinder radius="0.05" length="0.05"/>
            </geometry>
            <material name="black">
                <color rgba="0.0 0.0 0.0 1.0"/>
            </material>
        </visual>
        <collision>
            <origin xyz="-0.12 -0.1 0.0" rpy="0.0 1.5 0.0"/>
            <geometry>
                <cylinder radius="0.05" length="0.05"/>
            </geometry>
        </collision>
    </link>

    <joint name="joint_4" type="continuous">
        <parent link="base_link"/>
        <child link="wheel_4"/>
        <axis xyz="0 0 1"/>
        <origin xyz="-0.12 -0.1 0.0" rpy="0.0 1.5 0.0"/>
    </joint>
    
    
</robot>
