<?xml version="1.0"?>
<robot name="mikasa">
    <link name="world"/>

        <link name="base_link">
            <inertial>
                <origin xyz="0.0 0.0 0.025" rpy="0.0 0.0 0.0"/>
                <mass value="5.0"/>
                <inertia ixx="0.00554" ixy="0.0" ixz="0.0" iyy="0.00554" iyz="0.0" izz="0.009"/>
            </inertial>
            <visual>
                <origin xyz="0.0 0.0 0.025" rpy="0.0 0.0 0.0"/>
                <geometry>
                    <cylinder radius="0.06" length="0.05"/>
                </geometry>
                <material name="silver">
                    <color rgba="0.75 0.75 0.6 1.0"/>
                
                </material>
            </visual>
            <collision>
                <origin xyz="0.0 0.0 0.025" rpy="0.0 0.0 0.0"/>
                <geometry>
                    <cylinder radius="0.06" length="0.05"/>
                </geometry>
            </collision>
        </link>

        <joint name="fixed" type="fixed">
            <parent link="world"/>
            <child link="base_link"/>
            <origin xyz="0.0 0.0 0.0" rpy="0.0 0.0 0.0"/>
        </joint>

        <link name="link_1">
            <inertial>
                <origin xyz="0.0 0.0 0.025" rpy="0.0 0.0 0.0"/>
                <mass value="5.0"/>
                <inertia ixx="1.06175" ixy="0.0" ixz="0.0" iyy="1.06175" iyz="0.0" izz="0.004"/>
            </inertial>
            <visual>
                <origin xyz="0.0 0.0 0.25" rpy="0.0 0.0 0.0"/>
                <geometry>
                    <cylinder radius="0.04" length="0.5"/>
                </geometry>
                <material name="silver">
                    <color rgba="0.75 0.75 0.6 1.0"/>
                
                </material>
            </visual>
            <collision>
                <origin xyz="0.0 0.0 0.025" rpy="0.0 0.0 0.0"/>
                <geometry>
                    <cylinder radius="0.06" length="0.05"/>
                </geometry>
            </collision>
        </link>

        <joint name="joint_1" type="continuous">
            <parent link="base_link"/>
            <child link="link_1"/>
            <axis xyz="0 0 1"/>
            <origin xyz="0 0 0.05" rpy="0 0 0"/>
        </joint>

        <link name="link_2">
            <inertial>
                <origin xyz="0.0 0.0 0.20" rpy="0.0 0.0 0.0"/>
                <mass value="4.0"/>
                <inertia ixx="0.0833" ixy="0.0" ixz="0.0" iyy="0.0833" iyz="0.0" izz="0.0018"/>
            </inertial>
            <visual>
                <origin xyz="0.0 0.0 0.20" rpy="0.0 0.0 0.0"/>
                <geometry>
                    <cylinder radius="0.03" length="0.4"/>
                </geometry>
                <material name="silver">
                    <color rgba="0.75 0.75 0.6 1.0"/>
                
                </material>
            </visual>
            <collision>
                <origin xyz="0.0 0.0 0.20" rpy="0.0 0.0 0.0"/>
                <geometry>
                    <cylinder radius="0.03" length="0.4"/>
                </geometry>
            </collision>
        </link>

        <joint name="joint_2" type="continuous">
            <parent link="link_1"/>
            <child link="link_2"/>
            <axis xyz="0 1 0"/>
            <origin xyz="0 0.075 0.5" rpy="0 1.57 0"/>
        </joint>

        <link name="link_3">
            <inertial>
                <origin xyz="0.0 0.0 0.2" rpy="0.0 0.0 0.0"/>
                <mass value="4.0"/>
                <inertia ixx="1.06175" ixy="0.0" ixz="0.0" iyy="1.06175" iyz="0.0" izz="0.004"/>
            </inertial>
            <visual>
                <origin xyz="0.0 0.0 0.2" rpy="0.0 0.0 0.0"/>
                <geometry>
                    <cylinder radius="0.03" length="0.4"/>
                </geometry>
                <material name="silver">
                    <color rgba="0.75 0.75 0.6 1.0"/>
                
                </material>
            </visual>
            <collision>
                <origin xyz="0.0 0.0 0.2" rpy="0.0 0.0 0.0"/>
                <geometry>
                    <cylinder radius="0.03" length="0.4"/>
                </geometry>
            </collision>
        </link>

        <joint name="joint_3" type="continuous">
            <parent link="link_2"/>
            <child link="link_3"/>
            <axis xyz="0 1 0"/>
            <origin xyz="0.01 0.06 0.37" rpy="0 0 0"/>
        </joint>

        <link name="link_4">
            <inertial>
                <origin xyz="0.0 0.0 0.01" rpy="0.0 0.0 0.0"/>
                <mass value="0.5"/>
                <inertia ixx="0.000075" ixy="0.0" ixz="0.0" iyy="0.000075" iyz="0.0" izz="0.000075"/>
            </inertial>
            <visual>
                <origin xyz="0.0 0.0 0.01" rpy="0.0 0.0 0.0"/>
                <geometry>
                    <box size="0.03 0.03 0.03"/>
                </geometry>
                <material name="silver">
                    <color rgba="0.75 0.75 0.6 1.0"/>
                
                </material>
            </visual>
            <collision>
                <origin xyz="0.0 0.0 0.01" rpy="0.0 0.0 0.0"/>
                <geometry>
                    <box size="0.03 0.03 0.03"/>
                </geometry>
            </collision>
        </link>

        <joint name="joint_4" type="continuous">
            <parent link="link_3"/>
            <child link="link_4"/>
            <axis xyz="0 1 0"/>
            <origin xyz="0 0.0 0.40" rpy="0 0 0"/>
        </joint>


        <gazebo reference = "base_link">
            <material>Gazebo/Black</material>
        </gazebo>
        <gazebo reference = "link_1">
            <material>Gazebo/Orange</material>
        </gazebo>
        <gazebo reference = "link_2">
            <material>Gazebo/Grey</material>
        </gazebo>
        <gazebo reference= "link_3">
            <material>Gazebo/Black</material>
        </gazebo>
        <gazebo reference = "link_4">
            <material>Gazebo/Blue</material>
        </gazebo>

        <!-- PositionJointInterface -->
        <!-- EffortJointInterface -->

        <transmission name ="trans_1">
            <type>transmission_interface/SimpleTransmission</type>
            <joint name="joint_1">
                <hardwareInterface>hardware_interface/PositionJointInterface</hardwareInterface>
            </joint>
            <actuator name="motor_1">
                <hardwareInterface>hardware_interface/PositionJointInterface</hardwareInterface>
                <mechanicalReduction>1</mechanicalReduction>
            </actuator>
        </transmission>

        <transmission name ="trans_2">
            <type>transmission_interface/SimpleTransmission</type>
            <joint name="joint_2">
                <hardwareInterface>hardware_interface/PositionJointInterface</hardwareInterface>
            </joint>
            <actuator name="motor_2">
                <hardwareInterface>hardware_interface/PositionJointInterface</hardwareInterface>
                <mechanicalReduction>1</mechanicalReduction>
            </actuator>
        </transmission>

        <transmission name ="trans_3">
            <type>transmission_interface/SimpleTransmission</type>
            <joint name="joint_3">
                <hardwareInterface>hardware_interface/PositionJointInterface</hardwareInterface>
            </joint>
            <actuator name="motor_3">
                <hardwareInterface>hardware_interface/PositionJointInterface</hardwareInterface>
                <mechanicalReduction>1</mechanicalReduction>
            </actuator>
        </transmission>

        <transmission name ="trans_4">
            <type>transmission_interface/SimpleTransmission</type>
            <joint name="joint_4">
                <hardwareInterface>hardware_interface/PositionJointInterface</hardwareInterface>
            </joint>
            <actuator name="motor_4">
                <hardwareInterface>hardware_interface/PositionJointInterface</hardwareInterface>
                <mechanicalReduction>1</mechanicalReduction>
            </actuator>
        </transmission>

       
    
    
</robot>
